<?xml version="1.0"?>

<robot name="frederick" xmlns:xacro="http://www.ros.org/wiki/xacro">

<!-- Body dimensions -->
<xacro:property name="base_link_x_dim" value="0.28"/>
<xacro:property name="base_link_y_dim" value="0.10"/>
<xacro:property name="base_link_z_dim" value="0.09"/>
<xacro:property name="body_mass" value="0.5"/>


<!-- Wheel dimensions -->
<xacro:property name="wheel_link_radius" value="0.03"/>
<xacro:property name="wheel_link_length" value="0.025"/>
<xacro:property name="wheel_link_z_location" value="-0.03"/>
<xacro:property name="wheel_mass" value="0.05"/>

<!-- Pi constant -->
<xacro:property name="pi_const" value="3.14159265"/>

<!-- Moments of inertia of wheel -->
<xacro:property name="Iz_wheel" value="${0.5*wheel_mass*wheel_link_radius*wheel_link_radius}"/>
<xacro:property name="I_wheel" value="${(1.0/12.0)*wheel_mass*(3.0*wheel_link_radius*wheel_link_radius+wheel_link_length*wheel_link_length)}"/>


<xacro:macro name="inertia_wheel">
    <inertial>
        <origin rpy="0 0 0" xyz="0 0 0"/>
        <mass value="${wheel_mass}"/>
        <inertia ixx="${I_wheel}" ixy="0.0" ixz="0.0" iyy="${I_wheel}" iyz="0" izz="${Iz_wheel}"/>
    </inertial>
</xacro:macro>


<xacro:include filename="$(find frederick_model_pkg)/urdf/robot.gazebo" />


<!-- Dummy link-->
<link name="dummy"></link>
<joint name="dummy_joint" type="fixed">
	<parent link="dummy"/>
	<child link="base_link"/>
</joint>


<!-- Robot dimensions -->
<!-- Body Link -->
<link name="base_link">
    <visual>
        <geometry>
            <box size="${base_link_x_dim} ${base_link_y_dim} ${base_link_z_dim}"/>
        </geometry>
        <origin xyz="0 0 0" rpy="0 0 0"/>
    </visual>
    <collision>
        <geometry>
            <box size="${base_link_x_dim} ${base_link_y_dim} ${base_link_z_dim}"/>
        </geometry>
        <origin xyz="0 0 0" rpy="0 0 0"/>
    </collision>
    <inertial>
        <origin rpy="0 0 0" xyz="0 0 0"/>
        <mass value="${body_mass}"/>
        <inertia 
            ixx="${(1/12) * body_mass * (base_link_y_dim*base_link_y_dim + base_link_z_dim*base_link_z_dim)}"
            ixy="0" 
            ixz="0"
            iyy="${(1/12) * body_mass * (base_link_x_dim*base_link_x_dim + base_link_z_dim*base_link_z_dim)}"
            iyz="0"
            izz="${(1/12) * body_mass * (base_link_y_dim*base_link_y_dim + base_link_x_dim*base_link_x_dim)}"/>
    </inertial>
</link>

<!-- Example snippet to add RPLidar to URDF -->
<link name="rplidar_link">
  <visual>
    <geometry>
      <cylinder length="0.07" radius="0.0325"/>
    </geometry>
  </visual>
  <inertial>
    <mass value="0.17"/>
    <inertia ixx="0.1" ixy="0" ixz="0" iyy="0.1" iyz="0" izz="0.1"/>
  </inertial>
</link>

<joint name="rplidar_joint" type="fixed">
  <parent link="base_link"/>  <!-- Adjust base_link to where you want to attach the lidar -->
  <child link="rplidar_link"/>
  <origin xyz="-0.11 0 0.08" rpy="0 0 0"/>  <!-- Adjust position and orientation as needed -->
</joint>


<!-- Wheels -->
<!-- Rear right wheel-->
<joint name="wheel1_joint" type="continuous">
	<parent link="base_link"/>
        <child link="wheel1_link"/>
        <origin xyz="-0.06 -0.065 -0.03" rpy="0 0 0"/>
        <axis xyz="0 1 0"/>
        <limit effort="1000" velocity="1000"/>
        <dynamics damping="1.0" friction="1.0"/>
</joint>
<link name="wheel1_link">
        <visual>
            <origin rpy="1.570795 0 0" xyz="0 0 0"/>
            <geometry>
                <cylinder length="0.025" radius="0.03"/>
            </geometry>
            <material name="yellow">
                <color rgba="1 1 0 1"/>
            </material> 
	</visual>
	<collision>
            <origin rpy="1.570795 0 0" xyz="0 0 0"/>
            <geometry>
                <cylinder length="0.025" radius="0.03"/>
            </geometry>
	</collision>
	<xacro:inertia_wheel />
</link>

<!-- Rear left wheel -->
<joint name="wheel2_joint" type="continuous">
	<parent link="base_link"/>
        <child link="wheel2_link"/>
        <origin xyz="-0.06 0.065 -0.03" rpy="0 0 0"/>
        <axis xyz="0 1 0"/>
        <limit effort="1000" velocity="1000"/>
        <dynamics damping="1.0" friction="1.0"/>
</joint>
<link name="wheel2_link">
        <visual>
            <origin rpy="1.570795 0 0" xyz="0 0 0"/>
            <geometry>
                <cylinder length="0.025" radius="0.03"/>
            </geometry>
            <material name="yellow">
                <color rgba="1 1 0 1"/>
            </material> 
	</visual>
	<collision>
            <origin rpy="1.570795 0 0" xyz="0 0 0"/>
            <geometry>
                <cylinder length="0.025" radius="0.03"/>
            </geometry>
	</collision>
	<xacro:inertia_wheel />
</link>

<!-- Front right wheel -->
<joint name="wheel3_joint" type="continuous">
	<parent link="base_link"/>
        <child link="wheel3_link"/>
        <origin xyz="0.06 -0.065 -0.03" rpy="0 0 0"/>
        <axis xyz="0 1 0"/>
        <limit effort="1000" velocity="1000"/>
        <dynamics damping="1.0" friction="1.0"/>
</joint>
<link name="wheel3_link">
        <visual>
            <origin rpy="1.570795 0 0" xyz="0 0 0"/>
            <geometry>
                <cylinder length="0.025" radius="0.03"/>
            </geometry>
            <material name="yellow">
                <color rgba="1 1 0 1"/>
            </material> 
	</visual>
	<collision>
            <origin rpy="1.570795 0 0" xyz="0 0 0"/>
            <geometry>
                <cylinder length="0.025" radius="0.03"/>
            </geometry>
	</collision>
	<xacro:inertia_wheel />
</link>

<!-- Front left wheel -->
<joint name="wheel4_joint" type="continuous">
	<parent link="base_link"/>
        <child link="wheel4_link"/>
        <origin xyz="0.06 0.065 -0.03" rpy="0 0 0"/>
        <axis xyz="0 1 0"/>
        <limit effort="1000" velocity="1000"/>
        <dynamics damping="1.0" friction="1.0"/>
</joint>
<link name="wheel4_link">
        <visual>
            <origin rpy="1.570795 0 0" xyz="0 0 0"/>
            <geometry>
                <cylinder length="0.025" radius="0.03"/>
            </geometry>
            <material name="yellow">
                <color rgba="1 1 0 1"/>
            </material> 
	</visual>
	<collision>
            <origin rpy="1.570795 0 0" xyz="0 0 0"/>
            <geometry>
                <cylinder length="0.025" radius="0.03"/>
            </geometry>
	</collision>
	<xacro:inertia_wheel />
</link>



</robot>

